Workbook

Sheet 2.Plan
A1: 6 viviendas de 57 metros y 4 Viviendas de 47 metros | C1: Pagado ya | D1: Falta | E1: Porecntaje del total
A2: Contenido | B2: Costo | E2: OJO QUE NO SUMA 100%
A3: Valor de Compra | B3: 200000 | C3: 200000 | D3: =B3-C3 -> 0 | E3: =B3/$B$43 -> 0.11349987
A4: Impuesto ITP | B4: =B3*0.1 -> 20000 | C4: 20000 | D4: =B4-C4 -> 0 | E4: =B4/$B$43 -> 0.011349987
A5: Comision Inmobiliaria (IVA INC) | B5: =0.03*1.21 -> 0.0363 | D5: =B5-C5 -> 0.0363
A6: Comision en valor | B6: =B3*B5 -> 7260 | C6: 7260 | D6: =B6-C6 -> 0 | E6: =B6/$B$43 -> 0.0041200453
A7: Gestoria y registro (Estimado) | B7: 1700 | C7: 1700 | D7: =B7-C7 -> 0 | E7: =B7/$B$43 -> 0.00096474889
A9: Costo total compra | B9: =SUM(+B3+B4+B6+B7+B8) -> 228960 | E9: =B9/$B$43 -> 0.12993465
A11: Abogada | B11: 8000 | C11: 3872 | D11: =B11-C11 -> 4128 | E11: =B11/$B$43 -> 0.0045399948
A12: Topografia | B12: 907.5 | C12: 907.5 | D12: =B12-C12 -> 0 | E12: =B12/$B$43 -> 0.00051500566
A13: Gestor Financiero (18 MEses) | B13: =160*18 -> 2880 | C13: =160*6 -> 960 | D13: =B13-C13 -> 1920 | E13: =B13/$B$43 -> 0.0016343981
A14: ICIO | B14: 23766.64 | C14: 23766.64 | D14: =B14-C14 -> 0 | E14: =B14/$B$43 -> 0.013487553
A15: Tasa Urbanistica | B15: 9902.77 | C15: 9902.77 | D15: =B15-C15 -> 0 | E15: =B15/$B$43 -> 0.0056198155
A16: Arqueologo (Estimado) | B16: 2000 | C16: 371 | D16: =B16-C16 -> 1629 | E16: =B16/$B$43 -> 0.0011349987
A17: Diseño de interiores | B17: 6677 | C17: 2000 | D17: =B17-C17 -> 4677 | E17: =B17/$B$43 -> 0.0037891931
A18: Arquitecto y Arquitecto Técnico | B18: 53000 | C18: 19080 | D18: =B18-C18 -> 33920 | E18: =B18/$B$43 -> 0.030077465
A19: Iberdrola - Connexion de linea transformacion(Estimado) | B19: 23000 | D19: =B19-C19 -> 23000 | E19: =B19/$B$43 -> 0.013052485
A20: Estudio Geotecnico | B20: 1215 | C20: 1470.15 | D20: =B20-C20 -> -255.15 | E20: =B20/$B$43 -> 0.00068951171
A21: Proyecto de Telecomunicaciones | B21: 4000 | D21: =B21-C21 -> 4000 | E21: =B21/$B$43 -> 0.0022699974
A22: Construccion según presupuesto | B22: 1014982.7 | D22: =B22-C22 -> 1014982.7 | E22: =B22/$B$43 -> 0.57600201
A23: Resto Sofia | B23: 155000 | D23: =B23-C23 -> 155000 | E23: =B23/$B$43 -> 0.087962399
A24: OCT | B24: 3482 | D24: =B24-C24 -> 3482 | E24: =B24/$B$43 -> 0.0019760327
A25: Seguro Decenal | B25: 3000 | D25: =B25-C25 -> 3000 | E25: =B25/$B$43 -> 0.001702498
A26: Seguro RC | B26: 600 | E26: =B26/$B$43 -> 0.00034049961
A27: Seguro Afianzamiento | E27: =B27/$B$43 -> 0
A28: Notaria (Division horizontal, agrupacion, declaracion de obra en construccion) | B28: 35000 | D28: =B28-C28 -> 35000 | E28: =B28/$B$43 -> 0.019862477
A29: Conexion Hidraqua | B29: 4000 | D29: =B29-C29 -> 4000 | E29: =B29/$B$43 -> 0.0022699974
A30: Costo de amoblamiento total (Estimado) | B30: 180000 | D30: =B30-C30 -> 180000 | E30: =B30/$B$43 -> 0.10214988
A31: Cantidad de viviendas 47m | B31: 4 | C31: Falta Pagar | D31: =SUM(D3:D30) -> 1468483.6
A32: Cantidad de viviendas 57m | B32: 6
A33: Metros totales utiles solo viviendas | B33: 530
A34: Costo x metro utiles solo viviendas | B34: =B43/B33 -> 3324.7482
A35: Metros totales utiles | B35: 742
A36: Costo x metro totales utiles | B36: =B43/B35 -> 2374.8202
A37: Metros totales construidos | B37: 831
A38: Costo x metro totales construidos | B38: =B43/B37 -> 2120.4772
A39: Metros totales todo incluido (Inc. descubiertos) | B39: 1039
A40: Costo x metro todo incluido | B40: =B43/B39 -> 1695.9736
A41: Costo Total proyecto sim amoblamiento | B41: =sum(B9:B29) -> 1580373.6
A42: Costo financiero (11,5%) | B42: =B41*0.15 -> 237056.04
...

Sheet 7.Vision
A1: "La Hospitalidad Redefinida"
A3: Mision
A4: Redefinir la hospitalidad integrando vivienda, inversión y gestión profesional en un modelo digital, flexible y centrado en las personas, que eleve la experiencia de habitar e invertir a un nuevo estándar.
A6: Vision
A7: Ser una referencia en el desarrollo inmobiliario moderno, reconocida por integrar construcción, gestión y digitalización para transformar el acceso a la inversión inmobiliaria mediante modelos inteligentes, sostenibles y orientados al largo plazo, generando valor constante para inversores, residentes y comunidades.
A11: 10 razones para invertir en El Fortin de Riba Roja
A12: 1. Invertís en ladrillo, sin dolores de cabeza Real estate real, en España, sin lidiar con inquilinos, arreglos, seguros ni mantenimiento. Vos invertís, nosotros nos ocupamos de todo lo demás. 2. Rentabilidad clara y razonable: 6% a 9% anual Un rendimiento estimado sobre valor de tasación, pensado para quien busca ganar bien sin correr riesgos innecesarios. No promesas mágicas: números sólidos. 3. España: un mercado que viene creciendo hace 15 años El precio de la vivienda en España no para de crecer desde hace más de una década. No es una moda: es una tendencia sostenida. 4. Riba-roja: ciudad en expansión real No es una apuesta al azar. Riba-roja de Túria crece, recibe población nueva y cada vez está más integrada al área metropolitana de Valencia. 5. Valencia a un paso (y sin auto) Con metro directo a Valencia, vivís o alquilás con conexión rápida al centro, universidades, hospitales y empleo. Eso siempre suma valor. 6. Naturaleza al lado de casa Estar a metros del Parque del Río Turia no es un detalle: es calidad de vida. Y la calidad de vida se alquila mejor y se revaloriza más. 7. Gestión profesional, de punta a punta La administración queda en manos de profesionales que saben hacerlo mejor que nadie. Vos no improvisás ni aprendés a los golpes: entrás a un sistema que ya funciona. 8. Tu piso, cuando lo quieras Invertís, pero seguís teniendo la posibilidad de usar el piso una vez al año para vos o tu familia. No es solo números: también es disfrute. 9. Reinvertir y crecer, sin empezar de cero Si querés, podés reinvertir las ganancias en los próximos proyectos de El Fortín. Así armás un camino de crecimiento sin volver a buscar oportunidades desde cero. 10. Preventa con 10% de descuento. Solo 4 unidades! Entrar en preventa significa comprar mejor desde el día uno. Un 15% de descuento que impacta directo en tu rentabilidad futura.

Sheet 8.Ventas
A1: Puerta | B1: Sup Util | C1: Comprador | D1: Fecha | E1: Formato de venta | F1: Monto final | G1: Ya pago | H1: Comision
A2: 1 | B2: 49.05
A3: 2 | B3: 49.05
A4: 3 | B4: 49.05
A5: 4 | B5: 49.05
A6: 5 | B6: 40.48
A7: 6 | B7: 40.44
A8: 7 | B8: 40.44
A9: 8 | B9: 40.44
A10: 9 | B10: 49.05
A11: 10 | B11: 49.05 | C11: Alejandro Contenti y Daniela Hoffman | H11: =F11*0.02 -> 0

Sheet 9.Simulacion
B3: 47m | C3: 57m
A4: Alquiler mensual largo plazo | B4: 1150 | C4: 1300
A5: Alquiler mensual corto plazo | B5: 1400 | C5: 1650
A6: Alquiler mensual vacaciones (65% ocupacion) | B6: 2200 | C6: 2500
A7: Alquiler mensual vacaciones (80% ocupacion) | B7: 2750 | C7: 3125
A16: Unidades | B16: Tamaño | C16: Tipo de alquiler | D16: Ingresos anuales | E16: Gastos Limpieza | F16: Gastos adicionales | G16: Luz, Agua | H16: Seguro | I16: Comunidad | J16: Comision El Fortin % | K16: Comisiones El Fortin € | L16: Neto Ingresos | M16: Precio Piso Mercado | N16: Gastos compra | O16: Mobiliario | P16: Renta anual bruto | Q16: Renta anual inversion total
A17: 1 | B17: 47 | C17: Vacacional | D17: =B6*12 -> 26400 | E17: 1100 | F17: 200 | G17: 100 | H17: 300 | I17: ='5.Adm.Finca'!$B$16 -> #REF! | J17: 0.14 | K17: =D17*J17 -> 3696 | L17: =D17-E17-F17-G17-H17-I17-K17 -> #REF! | M17: ='2.Plan'!$B$49 -> 203108.95 | N17: =M17*0.12 -> 24373.074 | O17: ='2.Plan'!B$54 -> 15959.658 | P17: =L17/M17 -> #REF! | Q17: =L17/(M17+N17+O17) -> #REF!
A18: 2 | B18: 47 | C18: Vacacional | D18: =B6*12 -> 26400 | E18: 1100 | F18: 200 | G18: 100 | H18: 300 | I18: ='5.Adm.Finca'!$B$16 -> #REF! | J18: 0.14 | K18: =D18*J18 -> 3696 | L18: =D18-E18-F18-G18-H18-I18-K18 -> #REF! | M18: ='2.Plan'!$B$49 -> 203108.95 | N18: =M18*0.12 -> 24373.074 | O18: ='2.Plan'!B$54 -> 15959.658 | P18: =L18/M18 -> #REF! | Q18: =L18/(M18+N18+O18) -> #REF!
A19: 3 | B19: 47 | C19: Corta duracion | D19: =B5*11 -> 15400 | E19: 150 | F19: 200 | G19: 100 | H19: 300 | I19: ='5.Adm.Finca'!$B$16 -> #REF! | J19: 0.1 | K19: =D19*J19 -> 1540 | L19: =D19-E19-F19-G19-H19-I19-K19 -> #REF! | M19: ='2.Plan'!$B$49 -> 203108.95 | N19: =M19*0.12 -> 24373.074 | O19: ='2.Plan'!B$54 -> 15959.658 | P19: =L19/M19 -> #REF! | Q19: =L19/(M19+N19+O19) -> #REF!
A20: 4 | B20: 47 | C20: Corta duracion | D20: =B5*11 -> 15400 | E20: 150 | F20: 200 | G20: 100 | H20: 300 | I20: ='5.Adm.Finca'!$B$16 -> #REF! | J20: 0.1 | K20: =D20*J20 -> 1540 | L20: =D20-E20-F20-G20-H20-I20-K20 -> #REF! | M20: ='2.Plan'!$B$49 -> 203108.95 | N20: =M20*0.12 -> 24373.074 | O20: ='2.Plan'!B$54 -> 15959.658 | P20: =L20/M20 -> #REF! | Q20: =L20/(M20+N20+O20) -> #REF!
A21: 5 | B21: 57 | C21: Corta duracion | D21: =C5*11 -> 18150 | E21: 150 | F21: 200 | G21: 100 | H21: 300 | I21: ='5.Adm.Finca'!$B$16 -> #REF! | J21: 0.1 | K21: =D21*J21 -> 1815 | L21: =D21-E21-F21-G21-H21-I21-K21 -> #REF! | M21: ='2.Plan'!$B$48 -> 246352.47 | N21: =M21*0.12 -> 29562.297 | O21: ='2.Plan'!B$53 -> 19357.597 | P21: =L21/M21 -> #REF! | Q21: =L21/(M21+N21+O21) -> #REF!
A22: 6 | B22: 57 | C22: Vacacional | D22: =C6*11 -> 27500 | E22: 1100 | F22: 200 | G22: 100 | H22: 300 | I22: ='5.Adm.Finca'!$B$16 -> #REF! | J22: 0.14 | K22: =D22*J22 -> 3850 | L22: =D22-E22-F22-G22-H22-I22-K22 -> #REF! | M22: ='2.Plan'!$B$48 -> 246352.47 | N22: =M22*0.12 -> 29562.297 | O22: ='2.Plan'!B$53 -> 19357.597 | P22: =L22/M22 -> #REF! | Q22: =L22/(M22+N22+O22) -> #REF!
A23: 7 | B23: 57 | C23: Vacacional | D23: =C6*12 -> 30000 | E23: 1100 | F23: 200 | G23: 100 | H23: 300 | I23: ='5.Adm.Finca'!$B$16 -> #REF! | J23: 0.14 | K23: =D23*J23 -> 4200 | L23: =D23-E23-F23-G23-H23-I23-K23 -> #REF! | M23: ='2.Plan'!$B$48 -> 246352.47 | N23: =M23*0.12 -> 29562.297 | O23: ='2.Plan'!B$53 -> 19357.597 | P23: =L23/M23 -> #REF! | Q23: =L23/(M23+N23+O23) -> #REF!
A24: 8 | B24: 57 | C24: Vacacional | D24: =C6*12 -> 30000 | E24: 1100 | F24: 200 | G24: 100 | H24: 300 | I24: ='5.Adm.Finca'!$B$16 -> #REF! | J24: 0.14 | K24: =D24*J24 -> 4200 | L24: =D24-E24-F24-G24-H24-I24-K24 -> #REF! | M24: ='2.Plan'!$B$48 -> 246352.47 | N24: =M24*0.12 -> 29562.297 | O24: ='2.Plan'!B$53 -> 19357.597 | P24: =L24/M24 -> #REF! | Q24: =L24/(M24+N24+O24) -> #REF!
A25: 9 | B25: 57 | C25: Vacacional | D25: =C6*12 -> 30000 | E25: 1100 | F25: 200 | G25: 100 | H25: 300 | I25: ='5.Adm.Finca'!$B$16 -> #REF! | J25: 0.14 | K25: =D25*J25 -> 4200 | L25: =D25-E25-F25-G25-H25-I25-K25 -> #REF! | M25: ='2.Plan'!$B$48 -> 246352.47 | N25: =M25*0.12 -> 29562.297 | O25: ='2.Plan'!B$53 -> 19357.597 | P25: =L25/M25 -> #REF! | Q25: =L25/(M25+N25+O25) -> #REF!
A26: 10 | B26: 57 | C26: Larga Duracion Amoblado | D26: =C4*11 -> 14300 | E26: 100 | F26: 200 | G26: 100 | H26: 300 | I26: ='5.Adm.Finca'!$B$16 -> #REF! | J26: 0.08 | K26: =D26*J26 -> 1144 | L26: =D26-E26-F26-G26-H26-I26-K26 -> #REF! | M26: ='2.Plan'!$B$48 -> 246352.47 | N26: =M26*0.12 -> 29562.297 | O26: ='2.Plan'!B$53 -> 19357.597 | P26: =L26/M26 -> #REF! | Q26: =L26/(M26+N26+O26) -> #REF!
E27: =SUM(Simulacion_Deseado[Gastos Limpieza]) -> 7150 | K27: =sum(Simulacion_Deseado[Comisiones El Fortin €]) -> 29881 | L27: =sum(Simulacion_Deseado[Neto Ingresos]) -> #REF! | M27: =SUM(Simulacion_Deseado[Precio Piso Mercado]) -> 2290550.6 | N27: =SUM(Simulacion_Deseado[Gastos compra]) -> 274866.08 | O27: =SUM(Simulacion_Deseado[Mobiliario]) -> 179984.21 | P27: =L27/M27 -> #REF! | Q27: =L27/(M27+N27+O27) -> #REF!
A31: Unidades | B31: Tamaño | C31: Tipo de alquiler | D31: Ingresos anuales | E31: Gastos Limpieza | F31: Gastos adicionales | G31: Luz, Agua | H31: Seguro | I31: Comunidad | J31: Comision El Fortin % | K31: Comisiones El Fortin € | L31: Neto Ingresos | M31: Precio Piso Mercado | N31: Gastos compra | O31: Mobiliario | P31: Renta anual bruto | Q31: Renta anual inversion total
A32: 1 | B32: 47 | C32: Larga Duracion Amoblado | D32: =B$4*11 -> 12650 | E32: 100 | F32: 100 | G32: 100 | H32: 300 | I32: ='5.Adm.Finca'!$B$16 -> #REF! | J32: 0.08 | K32: =D32*J32 -> 1012 | L32: =D32-E32-F32-G32-H32-I32-K32 -> #REF! | M32: ='2.Plan'!$B$49 -> 203108.95 | N32: =M32*0.12 -> 24373.074 | O32: ='2.Plan'!B$54 -> 15959.658 | P32: =L32/M32 -> #REF! | Q32: =L32/(M32+N32+O32) -> #REF!
A33: 2 | B33: 47 | C33: Larga Duracion Amoblado | D33: =B$4*11 -> 12650 | E33: 100 | F33: 100 | G33: 100 | H33: 300 | I33: ='5.Adm.Finca'!$B$16 -> #REF! | J33: 0.08 | K33: =D33*J33 -> 1012 | L33: =D33-E33-F33-G33-H33-I33-K33 -> #REF! | M33: ='2.Plan'!$B$49 -> 203108.95 | N33: =M33*0.12 -> 24373.074 | O33: ='2.Plan'!B$54 -> 15959.658 | P33: =L33/M33 -> #REF! | Q33: =L33/(M33+N33+O33) -> #REF!
A34: 3 | B34: 47 | C34: Larga Duracion Amoblado | D34: =B$4*11 -> 12650 | E34: 100 | F34: 100 | G34: 100 | H34: 300 | I34: ='5.Adm.Finca'!$B$16 -> #REF! | J34: 0.08 | K34: =D34*J34 -> 1012 | L34: =D34-E34-F34-G34-H34-I34-K34 -> #REF! | M34: ='2.Plan'!$B$49 -> 203108.95 | N34: =M34*0.12 -> 24373.074 | O34: ='2.Plan'!B$54 -> 15959.658 | P34: =L34/M34 -> #REF! | Q34: =L34/(M34+N34+O34) -> #REF!
A35: 4 | B35: 47 | C35: Larga Duracion Amoblado | D35: =B$4*11 -> 12650 | E35: 100 | F35: 100 | G35: 100 | H35: 300 | I35: ='5.Adm.Finca'!$B$16 -> #REF! | J35: 0.08 | K35: =D35*J35 -> 1012 | L35: =D35-E35-F35-G35-H35-I35-K35 -> #REF! | M35: ='2.Plan'!$B$49 -> 203108.95 | N35: =M35*0.12 -> 24373.074 | O35: ='2.Plan'!B$54 -> 15959.658 | P35: =L35/M35 -> #REF! | Q35: =L35/(M35+N35+O35) -> #REF!
A36: 5 | B36: 57 | C36: Larga Duracion Amoblado | D36: =C$4*11 -> 14300 | E36: 100 | F36: 100 | G36: 100 | H36: 300 | I36: ='5.Adm.Finca'!$B$16 -> #REF! | J36: 0.08 | K36: =D36*J36 -> 1144 | L36: =D36-E36-F36-G36-H36-I36-K36 -> #REF! | M36: ='2.Plan'!$B$48 -> 246352.47 | N36: =M36*0.12 -> 29562.297 | O36: ='2.Plan'!B$53 -> 19357.597 | P36: =L36/M36 -> #REF! | Q36: =L36/(M36+N36+O36) -> #REF!
A37: 6 | B37: 57 | C37: Larga Duracion Amoblado | D37: =C$4*11 -> 14300 | E37: 100 | F37: 100 | G37: 100 | H37: 300 | I37: ='5.Adm.Finca'!$B$16 -> #REF! | J37: 0.08 | K37: =D37*J37 -> 1144 | L37: =D37-E37-F37-G37-H37-I37-K37 -> #REF! | M37: ='2.Plan'!$B$48 -> 246352.47 | N37: =M37*0.12 -> 29562.297 | O37: ='2.Plan'!B$53 -> 19357.597 | P37: =L37/M37 -> #REF! | Q37: =L37/(M37+N37+O37) -> #REF!
A38: 7 | B38: 57 | C38: Larga Duracion Amoblado | D38: =C$4*11 -> 14300 | E38: 100 | F38: 100 | G38: 100 | H38: 300 | I38: ='5.Adm.Finca'!$B$16 -> #REF! | J38: 0.08 | K38: =D38*J38 -> 1144 | L38: =D38-E38-F38-G38-H38-I38-K38 -> #REF! | M38: ='2.Plan'!$B$48 -> 246352.47 | N38: =M38*0.12 -> 29562.297 | O38: ='2.Plan'!B$53 -> 19357.597 | P38: =L38/M38 -> #REF! | Q38: =L38/(M38+N38+O38) -> #REF!
A39: 8 | B39: 57 | C39: Larga Duracion Amoblado | D39: =C$4*11 -> 14300 | E39: 100 | F39: 100 | G39: 100 | H39: 300 | I39: ='5.Adm.Finca'!$B$16 -> #REF! | J39: 0.08 | K39: =D39*J39 -> 1144 | L39: =D39-E39-F39-G39-H39-I39-K39 -> #REF! | M39: ='2.Plan'!$B$48 -> 246352.47 | N39: =M39*0.12 -> 29562.297 | O39: ='2.Plan'!B$53 -> 19357.597 | P39: =L39/M39 -> #REF! | Q39: =L39/(M39+N39+O39) -> #REF!
A40: 9 | B40: 57 | C40: Larga Duracion Amoblado | D40: =C$4*11 -> 14300 | E40: 100 | F40: 100 | G40: 100 | H40: 300 | I40: ='5.Adm.Finca'!$B$16 -> #REF! | J40: 0.08 | K40: =D40*J40 -> 1144 | L40: =D40-E40-F40-G40-H40-I40-K40 -> #REF! | M40: ='2.Plan'!$B$48 -> 246352.47 | N40: =M40*0.12 -> 29562.297 | O40: ='2.Plan'!B$53 -> 19357.597 | P40: =L40/M40 -> #REF! | Q40: =L40/(M40+N40+O40) -> #REF!
A41: 10 | B41: 57 | C41: Larga Duracion Amoblado | D41: =C$4*11 -> 14300 | E41: 100 | F41: 100 | G41: 100 | H41: 300 | I41: ='5.Adm.Finca'!$B$16 -> #REF! | J41: 0.08 | K41: =D41*J41 -> 1144 | L41: =D41-E41-F41-G41-H41-I41-K41 -> #REF! | M41: ='2.Plan'!$B$48 -> 246352.47 | N41: =M41*0.12 -> 29562.297 | O41: ='2.Plan'!B$53 -> 19357.597 | P41: =L41/M41 -> #REF! | Q41: =L41/(M41+N41+O41) -> #REF!
E42: =SUM(WWorst_Case_Scenario[Gastos Limpieza]) -> 1000 | F42: =SUM(WWorst_Case_Scenario[Gastos adicionales]) -> 1000 | G42: 100.00 € | H42: =SUM(WWorst_Case_Scenario[Seguro]) -> 3000 | I42: =SUM(WWorst_Case_Scenario[Comunidad]) -> #REF! | K42: =sum(WWorst_Case_Scenario[Comisiones El Fortin €]) -> 10912 | L42: =sum(WWorst_Case_Scenario[Neto Ingresos]) -> #REF! | M42: =SUM(WWorst_Case_Scenario[Precio Piso Mercado]) -> 2290550.6 | N42: =SUM(WWorst_Case_Scenario[Gastos compra]) -> 274866.08 | O42: =SUM(WWorst_Case_Scenario[Mobiliario]) -> 179984.21 | P42: =L42/M42 -> #REF! | Q42: =L42/(M42+N42+O42) -> #REF!
A46: Unidades | B46: Tamaño | C46: Tipo de alquiler | D46: Ingresos anuales | E46: Gastos Limpieza | F46: Gastos adicionales | G46: Luz, Agua | H46: Seguro | I46: Comunidad | J46: Comision El Fortin % | K46: Comisiones El Fortin € | L46: Neto Ingresos | M46: Precio Piso Mercado | N46: Gastos compra | O46: Mobiliario | P46: Renta anual bruto | Q46: Renta anual inversion total
A47: 1 | B47: 47 | C47: Vacacional | D47: =B$7*12 -> 33000 | E47: 1100 | F47: 200 | G47: 150 | H47: 300 | I47: ='5.Adm.Finca'!$B$16 -> #REF! | J47: 0.14 | K47: =D47*J47 -> 4620 | L47: =D47-E47-F47-G47-H47-I47-K47 -> #REF! | M47: ='2.Plan'!$B$49 -> 203108.95 | N47: =M47*0.12 -> 24373.074 | O47: ='2.Plan'!B$54 -> 15959.658 | P47: =L47/M47 -> #REF! | Q47: =L47/(M47+N47+O47) -> #REF!
A48: 2 | B48: 47 | C48: Vacacional | D48: =B$7*12 -> 33000 | E48: 1100 | F48: 200 | G48: 150 | H48: 300 | I48: ='5.Adm.Finca'!$B$16 -> #REF! | J48: 0.14 | K48: =D48*J48 -> 4620 | L48: =D48-E48-F48-G48-H48-I48-K48 -> #REF! | M48: ='2.Plan'!$B$49 -> 203108.95 | N48: =M48*0.12 -> 24373.074 | O48: ='2.Plan'!B$54 -> 15959.658 | P48: =L48/M48 -> #REF! | Q48: =L48/(M48+N48+O48) -> #REF!
A49: 3 | B49: 47 | C49: Vacacional | D49: =B$7*12 -> 33000 | E49: 1100 | F49: 200 | G49: 150 | H49: 300 | I49: ='5.Adm.Finca'!$B$16 -> #REF! | J49: 0.14 | K49: =D49*J49 -> 4620 | L49: =D49-E49-F49-G49-H49-I49-K49 -> #REF! | M49: ='2.Plan'!$B$49 -> 203108.95 | N49: =M49*0.12 -> 24373.074 | O49: ='2.Plan'!B$54 -> 15959.658 | P49: =L49/M49 -> #REF! | Q49: =L49/(M49+N49+O49) -> #REF!
A50: 4 | B50: 47 | C50: Vacacional | D50: =B$7*12 -> 33000 | E50: 1100 | F50: 200 | G50: 150 | H50: 300 | I50: ='5.Adm.Finca'!$B$16 -> #REF! | J50: 0.14 | K50: =D50*J50 -> 4620 | L50: =D50-E50-F50-G50-H50-I50-K50 -> #REF! | M50: ='2.Plan'!$B$49 -> 203108.95 | N50: =M50*0.12 -> 24373.074 | O50: ='2.Plan'!B$54 -> 15959.658 | P50: =L50/M50 -> #REF! | Q50: =L50/(M50+N50+O50) -> #REF!
A51: 5 | B51: 57 | C51: Vacacional | D51: =C$7*12 -> 37500 | E51: 1100 | F51: 200 | G51: 150 | H51: 300 | I51: ='5.Adm.Finca'!$B$16 -> #REF! | J51: 0.14 | K51: =D51*J51 -> 5250 | L51: =D51-E51-F51-G51-H51-I51-K51 -> #REF! | M51: ='2.Plan'!$B$48 -> 246352.47 | N51: =M51*0.12 -> 29562.297 | O51: ='2.Plan'!B$53 -> 19357.597 | P51: =L51/M51 -> #REF! | Q51: =L51/(M51+N51+O51) -> #REF!
A52: 6 | B52: 57 | C52: Vacacional | D52: =C$7*12 -> 37500 | E52: 1100 | F52: 200 | G52: 150 | H52: 300 | I52: ='5.Adm.Finca'!$B$16 -> #REF! | J52: 0.14 | K52: =D52*J52 -> 5250 | L52: =D52-E52-F52-G52-H52-I52-K52 -> #REF! | M52: ='2.Plan'!$B$48 -> 246352.47 | N52: =M52*0.12 -> 29562.297 | O52: ='2.Plan'!B$53 -> 19357.597 | P52: =L52/M52 -> #REF! | Q52: =L52/(M52+N52+O52) -> #REF!
A53: 7 | B53: 57 | C53: Vacacional | D53: =C$7*12 -> 37500 | E53: 1100 | F53: 200 | G53: 150 | H53: 300 | I53: ='5.Adm.Finca'!$B$16 -> #REF! | J53: 0.14 | K53: =D53*J53 -> 5250 | L53: =D53-E53-F53-G53-H53-I53-K53 -> #REF! | M53: ='2.Plan'!$B$48 -> 246352.47 | N53: =M53*0.12 -> 29562.297 | O53: ='2.Plan'!B$53 -> 19357.597 | P53: =L53/M53 -> #REF! | Q53: =L53/(M53+N53+O53) -> #REF!
A54: 8 | B54: 57 | C54: Vacacional | D54: =C$7*12 -> 37500 | E54: 1100 | F54: 200 | G54: 150 | H54: 300 | I54: ='5.Adm.Finca'!$B$16 -> #REF! | J54: 0.14 | K54: =D54*J54 -> 5250 | L54: =D54-E54-F54-G54-H54-I54-K54 -> #REF! | M54: ='2.Plan'!$B$48 -> 246352.47 | N54: =M54*0.12 -> 29562.297 | O54: ='2.Plan'!B$53 -> 19357.597 | P54: =L54/M54 -> #REF! | Q54: =L54/(M54+N54+O54) -> #REF!
A55: 9 | B55: 57 | C55: Vacacional | D55: =C$7*12 -> 37500 | E55: 1100 | F55: 200 | G55: 150 | H55: 300 | I55: ='5.Adm.Finca'!$B$16 -> #REF! | J55: 0.14 | K55: =D55*J55 -> 5250 | L55: =D55-E55-F55-G55-H55-I55-K55 -> #REF! | M55: ='2.Plan'!$B$48 -> 246352.47 | N55: =M55*0.12 -> 29562.297 | O55: ='2.Plan'!B$53 -> 19357.597 | P55: =L55/M55 -> #REF! | Q55: =L55/(M55+N55+O55) -> #REF!
A56: 10 | B56: 57 | C56: Vacacional | D56: =C$7*12 -> 37500 | E56: 1100 | F56: 200 | G56: 150 | H56: 300 | I56: ='5.Adm.Finca'!$B$16 -> #REF! | J56: 0.14 | K56: =D56*J56 -> 5250 | L56: =D56-E56-F56-G56-H56-I56-K56 -> #REF! | M56: ='2.Plan'!$B$48 -> 246352.47 | N56: =M56*0.12 -> 29562.297 | O56: ='2.Plan'!B$53 -> 19357.597 | P56: =L56/M56 -> #REF! | Q56: =L56/(M56+N56+O56) -> #REF!
...

Sheet 12.% m2
A1: Puerta | B1: Sup Util | C1: Poinderacion | D1: Valor ponderado | E1: Comunidad de vecinos | F1: Comunidad de bienes | G1: Columna 1
A2: 1 | B2: 49.05 | C2: 1 | D2: =B2*C2 -> 49.05 | E2: =D2/$D$13 -> 0.10144568 | F2: =D2/Tabla_4[[#TOTALS],[Sup Util]] -> 0.10754221
A3: 2 | B3: 49.05 | C3: 1 | D3: =B3*C3 -> 49.05 | E3: =D3/$D$13 -> 0.10144568 | F3: =D3/Tabla_4[[#TOTALS],[Sup Util]] -> 0.10754221
A4: 3 | B4: 49.05 | C4: 1 | D4: =B4*C4 -> 49.05 | E4: =D4/$D$13 -> 0.10144568 | F4: =D4/Tabla_4[[#TOTALS],[Sup Util]] -> 0.10754221
A5: 4 | B5: 49.05 | C5: 1 | D5: =B5*C5 -> 49.05 | E5: =D5/$D$13 -> 0.10144568 | F5: =D5/Tabla_4[[#TOTALS],[Sup Util]] -> 0.10754221
A6: 5 | B6: 40.48 | C6: 1 | D6: =B6*C6 -> 40.48 | E6: =D6/$D$13 -> 0.083721123 | F6: =D6/Tabla_4[[#TOTALS],[Sup Util]] -> 0.088752467
A7: 6 | B7: 40.44 | C7: 1 | D7: =B7*C7 -> 40.44 | E7: =D7/$D$13 -> 0.083638394 | F7: =D7/Tabla_4[[#TOTALS],[Sup Util]] -> 0.088664767
A8: 7 | B8: 40.44 | C8: 1 | D8: =B8*C8 -> 40.44 | E8: =D8/$D$13 -> 0.083638394 | F8: =D8/Tabla_4[[#TOTALS],[Sup Util]] -> 0.088664767
A9: 8 | B9: 40.44 | C9: 1 | D9: =B9*C9 -> 40.44 | E9: =D9/$D$13 -> 0.083638394 | F9: =D9/Tabla_4[[#TOTALS],[Sup Util]] -> 0.088664767
A10: 9 | B10: 49.05 | C10: 1 | D10: =B10*C10 -> 49.05 | E10: =D10/$D$13 -> 0.10144568 | F10: =D10/Tabla_4[[#TOTALS],[Sup Util]] -> 0.10754221
A11: 10 | B11: 49.05 | C11: 1 | D11: =B11*C11 -> 49.05 | E11: =D11/$D$13 -> 0.10144568 | F11: =D11/Tabla_4[[#TOTALS],[Sup Util]] -> 0.10754221
A12: Garajes | B12: 54.82 | C12: 0.5 | D12: =B12*C12 -> 27.41 | E12: =D12/$D$13 -> 0.056689624
B13: =SUM(B2:B12) -> 510.92 | D13: =SUM(D2:D12) -> 483.51 | E13: =D13/$D$13 -> 1
B14: =SUM(B2:B11) -> 456.1
